[2024-11-25T18:27:48.540+0000] {local_task_job_runner.py:123} INFO - ::group::Pre task execution logs
[2024-11-25T18:27:48.570+0000] {taskinstance.py:2613} INFO - Dependencies all met for dep_context=non-requeueable deps ti=<TaskInstance: etlDagV18.transformData scheduled__2024-11-25T17:00:00+00:00 [queued]>
[2024-11-25T18:27:48.587+0000] {taskinstance.py:2613} INFO - Dependencies all met for dep_context=requeueable deps ti=<TaskInstance: etlDagV18.transformData scheduled__2024-11-25T17:00:00+00:00 [queued]>
[2024-11-25T18:27:48.588+0000] {taskinstance.py:2866} INFO - Starting attempt 2 of 4
[2024-11-25T18:27:48.608+0000] {taskinstance.py:2889} INFO - Executing <Task(PythonOperator): transformData> on 2024-11-25 17:00:00+00:00
[2024-11-25T18:27:48.644+0000] {logging_mixin.py:190} WARNING - /home/***/.local/lib/python3.12/site-packages/***/task/task_runner/standard_task_runner.py:70 DeprecationWarning: This process (pid=7537) is multi-threaded, use of fork() may lead to deadlocks in the child.
[2024-11-25T18:27:48.648+0000] {standard_task_runner.py:72} INFO - Started process 7547 to run task
[2024-11-25T18:27:48.644+0000] {standard_task_runner.py:104} INFO - Running: ['***', 'tasks', 'run', 'etlDagV18', 'transformData', 'scheduled__2024-11-25T17:00:00+00:00', '--job-id', '107', '--raw', '--subdir', 'DAGS_FOLDER/etlDag.py', '--cfg-path', '/tmp/tmp40gbdz73']
[2024-11-25T18:27:48.659+0000] {standard_task_runner.py:105} INFO - Job 107: Subtask transformData
[2024-11-25T18:27:48.868+0000] {task_command.py:467} INFO - Running <TaskInstance: etlDagV18.transformData scheduled__2024-11-25T17:00:00+00:00 [running]> on host 8bc87a2683b7
[2024-11-25T18:27:49.104+0000] {taskinstance.py:3132} INFO - Exporting env vars: AIRFLOW_CTX_DAG_OWNER='Oshith Roshantha' AIRFLOW_CTX_DAG_ID='etlDagV18' AIRFLOW_CTX_TASK_ID='transformData' AIRFLOW_CTX_EXECUTION_DATE='2024-11-25T17:00:00+00:00' AIRFLOW_CTX_TRY_NUMBER='2' AIRFLOW_CTX_DAG_RUN_ID='scheduled__2024-11-25T17:00:00+00:00'
[2024-11-25T18:27:49.110+0000] {taskinstance.py:731} INFO - ::endgroup::
[2024-11-25T18:27:49.215+0000] {_universal.py:509} INFO - Request URL: 'https://eqdatastorage.blob.core.windows.net/staging-data/cleaned-data.parquet'
Request method: 'GET'
Request headers:
    'x-ms-range': 'REDACTED'
    'x-ms-version': 'REDACTED'
    'Accept': 'application/xml'
    'User-Agent': 'azsdk-python-storage-blob/12.24.0 Python/3.12.7 (Linux-5.15.153.1-microsoft-standard-WSL2-x86_64-with-glibc2.36)'
    'x-ms-date': 'REDACTED'
    'x-ms-client-request-id': 'f970fe72-ab5a-11ef-b577-0242ac120004'
    'Authorization': 'REDACTED'
No body was attached to the request
[2024-11-25T18:27:51.284+0000] {_universal.py:545} INFO - Response status: 206
Response headers:
    'Content-Length': '661275'
    'Content-Type': 'application/octet-stream'
    'Content-Range': 'REDACTED'
    'Last-Modified': 'Mon, 25 Nov 2024 18:20:51 GMT'
    'Accept-Ranges': 'REDACTED'
    'ETag': '"0x8DD0D7DE4DAACBC"'
    'Server': 'Windows-Azure-Blob/1.0 Microsoft-HTTPAPI/2.0'
    'x-ms-request-id': '00f406c4-c01e-001e-7867-3f887a000000'
    'x-ms-client-request-id': 'f970fe72-ab5a-11ef-b577-0242ac120004'
    'x-ms-version': 'REDACTED'
    'x-ms-resource-type': 'REDACTED'
    'x-ms-creation-time': 'REDACTED'
    'x-ms-blob-content-md5': 'REDACTED'
    'x-ms-lease-status': 'REDACTED'
    'x-ms-lease-state': 'REDACTED'
    'x-ms-blob-type': 'REDACTED'
    'x-ms-server-encrypted': 'REDACTED'
    'x-ms-owner': 'REDACTED'
    'x-ms-group': 'REDACTED'
    'x-ms-permissions': 'REDACTED'
    'x-ms-acl': 'REDACTED'
    'Date': 'Mon, 25 Nov 2024 18:27:51 GMT'
[2024-11-25T18:28:37.810+0000] {_universal.py:506} INFO - Request URL: 'https://eqdatastorage.blob.core.windows.net/staging-data/transform-data.parquet'
Request method: 'PUT'
Request headers:
    'Content-Length': '7001008'
    'x-ms-blob-type': 'REDACTED'
    'x-ms-version': 'REDACTED'
    'Content-Type': 'application/octet-stream'
    'Accept': 'application/xml'
    'User-Agent': 'azsdk-python-storage-blob/12.24.0 Python/3.12.7 (Linux-5.15.153.1-microsoft-standard-WSL2-x86_64-with-glibc2.36)'
    'x-ms-date': 'REDACTED'
    'x-ms-client-request-id': '16682492-ab5b-11ef-b577-0242ac120004'
    'Authorization': 'REDACTED'
A body is sent with the request
[2024-11-25T18:29:00.235+0000] {job.py:239} ERROR - Job heartbeat failed with error
Traceback (most recent call last):
  File "/home/airflow/.local/lib/python3.12/site-packages/sqlalchemy/engine/base.py", line 3371, in _wrap_pool_connect
    return fn()
           ^^^^
  File "/home/airflow/.local/lib/python3.12/site-packages/sqlalchemy/pool/base.py", line 327, in connect
    return _ConnectionFairy._checkout(self)
           ^^^^^^^^^^^^^^^^^^^^^^^^^^^^^^^^
  File "/home/airflow/.local/lib/python3.12/site-packages/sqlalchemy/pool/base.py", line 894, in _checkout
    fairy = _ConnectionRecord.checkout(pool)
            ^^^^^^^^^^^^^^^^^^^^^^^^^^^^^^^^
  File "/home/airflow/.local/lib/python3.12/site-packages/sqlalchemy/pool/base.py", line 493, in checkout
    rec = pool._do_get()
          ^^^^^^^^^^^^^^
  File "/home/airflow/.local/lib/python3.12/site-packages/sqlalchemy/pool/impl.py", line 256, in _do_get
    return self._create_connection()
           ^^^^^^^^^^^^^^^^^^^^^^^^^
  File "/home/airflow/.local/lib/python3.12/site-packages/sqlalchemy/pool/base.py", line 273, in _create_connection
    return _ConnectionRecord(self)
           ^^^^^^^^^^^^^^^^^^^^^^^
  File "/home/airflow/.local/lib/python3.12/site-packages/sqlalchemy/pool/base.py", line 388, in __init__
    self.__connect()
  File "/home/airflow/.local/lib/python3.12/site-packages/sqlalchemy/pool/base.py", line 690, in __connect
    with util.safe_reraise():
         ^^^^^^^^^^^^^^^^^^^
  File "/home/airflow/.local/lib/python3.12/site-packages/sqlalchemy/util/langhelpers.py", line 70, in __exit__
    compat.raise_(
  File "/home/airflow/.local/lib/python3.12/site-packages/sqlalchemy/util/compat.py", line 211, in raise_
    raise exception
  File "/home/airflow/.local/lib/python3.12/site-packages/sqlalchemy/pool/base.py", line 686, in __connect
    self.dbapi_connection = connection = pool._invoke_creator(self)
                                         ^^^^^^^^^^^^^^^^^^^^^^^^^^
  File "/home/airflow/.local/lib/python3.12/site-packages/sqlalchemy/engine/create.py", line 574, in connect
    return dialect.connect(*cargs, **cparams)
           ^^^^^^^^^^^^^^^^^^^^^^^^^^^^^^^^^^
  File "/home/airflow/.local/lib/python3.12/site-packages/sqlalchemy/engine/default.py", line 598, in connect
    return self.dbapi.connect(*cargs, **cparams)
           ^^^^^^^^^^^^^^^^^^^^^^^^^^^^^^^^^^^^^
  File "/home/airflow/.local/lib/python3.12/site-packages/psycopg2/__init__.py", line 122, in connect
    conn = _connect(dsn, connection_factory=connection_factory, **kwasync)
           ^^^^^^^^^^^^^^^^^^^^^^^^^^^^^^^^^^^^^^^^^^^^^^^^^^^^^^^^^^^^^^^
psycopg2.OperationalError: could not translate host name "postgres" to address: Temporary failure in name resolution


The above exception was the direct cause of the following exception:

Traceback (most recent call last):
  File "/home/airflow/.local/lib/python3.12/site-packages/airflow/jobs/job.py", line 233, in heartbeat
    heartbeat_callback(session)
  File "/home/airflow/.local/lib/python3.12/site-packages/airflow/utils/session.py", line 94, in wrapper
    return func(*args, **kwargs)
           ^^^^^^^^^^^^^^^^^^^^^
  File "/home/airflow/.local/lib/python3.12/site-packages/airflow/jobs/local_task_job_runner.py", line 284, in heartbeat_callback
    self.task_instance.refresh_from_db()
  File "/home/airflow/.local/lib/python3.12/site-packages/airflow/utils/session.py", line 97, in wrapper
    return func(*args, session=session, **kwargs)
           ^^^^^^^^^^^^^^^^^^^^^^^^^^^^^^^^^^^^^^
  File "/home/airflow/.local/lib/python3.12/site-packages/airflow/models/taskinstance.py", line 2359, in refresh_from_db
    _refresh_from_db(task_instance=self, session=session, lock_for_update=lock_for_update)
  File "/home/airflow/.local/lib/python3.12/site-packages/airflow/models/taskinstance.py", line 872, in _refresh_from_db
    ti = TaskInstance.get_task_instance(
         ^^^^^^^^^^^^^^^^^^^^^^^^^^^^^^^
  File "/home/airflow/.local/lib/python3.12/site-packages/airflow/api_internal/internal_api_call.py", line 166, in wrapper
    return func(*args, **kwargs)
           ^^^^^^^^^^^^^^^^^^^^^
  File "/home/airflow/.local/lib/python3.12/site-packages/airflow/utils/session.py", line 94, in wrapper
    return func(*args, **kwargs)
           ^^^^^^^^^^^^^^^^^^^^^
  File "/home/airflow/.local/lib/python3.12/site-packages/airflow/models/taskinstance.py", line 2345, in get_task_instance
    return query.one_or_none()
           ^^^^^^^^^^^^^^^^^^^
  File "/home/airflow/.local/lib/python3.12/site-packages/sqlalchemy/orm/query.py", line 2850, in one_or_none
    return self._iter().one_or_none()
           ^^^^^^^^^^^^
  File "/home/airflow/.local/lib/python3.12/site-packages/sqlalchemy/orm/query.py", line 2916, in _iter
    result = self.session.execute(
             ^^^^^^^^^^^^^^^^^^^^^
  File "/home/airflow/.local/lib/python3.12/site-packages/sqlalchemy/orm/session.py", line 1716, in execute
    conn = self._connection_for_bind(bind)
           ^^^^^^^^^^^^^^^^^^^^^^^^^^^^^^^
  File "/home/airflow/.local/lib/python3.12/site-packages/sqlalchemy/orm/session.py", line 1555, in _connection_for_bind
    return self._transaction._connection_for_bind(
           ^^^^^^^^^^^^^^^^^^^^^^^^^^^^^^^^^^^^^^^
  File "/home/airflow/.local/lib/python3.12/site-packages/sqlalchemy/orm/session.py", line 750, in _connection_for_bind
    conn = bind.connect()
           ^^^^^^^^^^^^^^
  File "/home/airflow/.local/lib/python3.12/site-packages/sqlalchemy/future/engine.py", line 412, in connect
    return super(Engine, self).connect()
           ^^^^^^^^^^^^^^^^^^^^^^^^^^^^^
  File "/home/airflow/.local/lib/python3.12/site-packages/sqlalchemy/engine/base.py", line 3325, in connect
    return self._connection_cls(self, close_with_result=close_with_result)
           ^^^^^^^^^^^^^^^^^^^^^^^^^^^^^^^^^^^^^^^^^^^^^^^^^^^^^^^^^^^^^^^
  File "/home/airflow/.local/lib/python3.12/site-packages/sqlalchemy/engine/base.py", line 96, in __init__
    else engine.raw_connection()
         ^^^^^^^^^^^^^^^^^^^^^^^
  File "/home/airflow/.local/lib/python3.12/site-packages/sqlalchemy/engine/base.py", line 3404, in raw_connection
    return self._wrap_pool_connect(self.pool.connect, _connection)
           ^^^^^^^^^^^^^^^^^^^^^^^^^^^^^^^^^^^^^^^^^^^^^^^^^^^^^^^
  File "/home/airflow/.local/lib/python3.12/site-packages/sqlalchemy/engine/base.py", line 3374, in _wrap_pool_connect
    Connection._handle_dbapi_exception_noconnection(
  File "/home/airflow/.local/lib/python3.12/site-packages/sqlalchemy/engine/base.py", line 2208, in _handle_dbapi_exception_noconnection
    util.raise_(
  File "/home/airflow/.local/lib/python3.12/site-packages/sqlalchemy/util/compat.py", line 211, in raise_
    raise exception
  File "/home/airflow/.local/lib/python3.12/site-packages/sqlalchemy/engine/base.py", line 3371, in _wrap_pool_connect
    return fn()
           ^^^^
  File "/home/airflow/.local/lib/python3.12/site-packages/sqlalchemy/pool/base.py", line 327, in connect
    return _ConnectionFairy._checkout(self)
           ^^^^^^^^^^^^^^^^^^^^^^^^^^^^^^^^
  File "/home/airflow/.local/lib/python3.12/site-packages/sqlalchemy/pool/base.py", line 894, in _checkout
    fairy = _ConnectionRecord.checkout(pool)
            ^^^^^^^^^^^^^^^^^^^^^^^^^^^^^^^^
  File "/home/airflow/.local/lib/python3.12/site-packages/sqlalchemy/pool/base.py", line 493, in checkout
    rec = pool._do_get()
          ^^^^^^^^^^^^^^
  File "/home/airflow/.local/lib/python3.12/site-packages/sqlalchemy/pool/impl.py", line 256, in _do_get
    return self._create_connection()
           ^^^^^^^^^^^^^^^^^^^^^^^^^
  File "/home/airflow/.local/lib/python3.12/site-packages/sqlalchemy/pool/base.py", line 273, in _create_connection
    return _ConnectionRecord(self)
           ^^^^^^^^^^^^^^^^^^^^^^^
  File "/home/airflow/.local/lib/python3.12/site-packages/sqlalchemy/pool/base.py", line 388, in __init__
    self.__connect()
  File "/home/airflow/.local/lib/python3.12/site-packages/sqlalchemy/pool/base.py", line 690, in __connect
    with util.safe_reraise():
         ^^^^^^^^^^^^^^^^^^^
  File "/home/airflow/.local/lib/python3.12/site-packages/sqlalchemy/util/langhelpers.py", line 70, in __exit__
    compat.raise_(
  File "/home/airflow/.local/lib/python3.12/site-packages/sqlalchemy/util/compat.py", line 211, in raise_
    raise exception
  File "/home/airflow/.local/lib/python3.12/site-packages/sqlalchemy/pool/base.py", line 686, in __connect
    self.dbapi_connection = connection = pool._invoke_creator(self)
                                         ^^^^^^^^^^^^^^^^^^^^^^^^^^
  File "/home/airflow/.local/lib/python3.12/site-packages/sqlalchemy/engine/create.py", line 574, in connect
    return dialect.connect(*cargs, **cparams)
           ^^^^^^^^^^^^^^^^^^^^^^^^^^^^^^^^^^
  File "/home/airflow/.local/lib/python3.12/site-packages/sqlalchemy/engine/default.py", line 598, in connect
    return self.dbapi.connect(*cargs, **cparams)
           ^^^^^^^^^^^^^^^^^^^^^^^^^^^^^^^^^^^^^
  File "/home/airflow/.local/lib/python3.12/site-packages/psycopg2/__init__.py", line 122, in connect
    conn = _connect(dsn, connection_factory=connection_factory, **kwasync)
           ^^^^^^^^^^^^^^^^^^^^^^^^^^^^^^^^^^^^^^^^^^^^^^^^^^^^^^^^^^^^^^^
sqlalchemy.exc.OperationalError: (psycopg2.OperationalError) could not translate host name "postgres" to address: Temporary failure in name resolution

(Background on this error at: https://sqlalche.me/e/14/e3q8)
[2024-11-25T18:29:00.417+0000] {job.py:254} ERROR - Job heartbeat failed with error. Scheduler is in unhealthy state
[2024-11-25T18:29:00.438+0000] {local_task_job_runner.py:266} INFO - Task exited with return code -9. For more information, see https://***.apache.org/docs/apache-***/stable/troubleshooting.html#LocalTaskJob-killed
[2024-11-25T18:29:01.217+0000] {taskinstance.py:3895} INFO - 0 downstream tasks scheduled from follow-on schedule check
[2024-11-25T18:29:01.229+0000] {local_task_job_runner.py:245} INFO - ::endgroup::
