[2024-11-24T13:00:03.534+0000] {local_task_job_runner.py:123} INFO - ::group::Pre task execution logs
[2024-11-24T13:00:03.608+0000] {taskinstance.py:2613} INFO - Dependencies all met for dep_context=non-requeueable deps ti=<TaskInstance: etl_Pipeline.fetchData scheduled__2024-11-24T12:00:00+00:00 [queued]>
[2024-11-24T13:00:03.640+0000] {taskinstance.py:2613} INFO - Dependencies all met for dep_context=requeueable deps ti=<TaskInstance: etl_Pipeline.fetchData scheduled__2024-11-24T12:00:00+00:00 [queued]>
[2024-11-24T13:00:03.641+0000] {taskinstance.py:2866} INFO - Starting attempt 1 of 4
[2024-11-24T13:00:03.695+0000] {taskinstance.py:2889} INFO - Executing <Task(PythonOperator): fetchData> on 2024-11-24 12:00:00+00:00
[2024-11-24T13:00:03.716+0000] {standard_task_runner.py:104} INFO - Running: ['***', 'tasks', 'run', 'etl_Pipeline', 'fetchData', 'scheduled__2024-11-24T12:00:00+00:00', '--job-id', '4', '--raw', '--subdir', 'DAGS_FOLDER/etlDag.py', '--cfg-path', '/tmp/tmpag2cc8a2']
[2024-11-24T13:00:03.719+0000] {logging_mixin.py:190} WARNING - /home/***/.local/lib/python3.12/site-packages/***/task/task_runner/standard_task_runner.py:70 DeprecationWarning: This process (pid=525) is multi-threaded, use of fork() may lead to deadlocks in the child.
[2024-11-24T13:00:03.721+0000] {standard_task_runner.py:105} INFO - Job 4: Subtask fetchData
[2024-11-24T13:00:03.722+0000] {standard_task_runner.py:72} INFO - Started process 526 to run task
[2024-11-24T13:00:03.844+0000] {task_command.py:467} INFO - Running <TaskInstance: etl_Pipeline.fetchData scheduled__2024-11-24T12:00:00+00:00 [running]> on host 9ad32cb2e65e
[2024-11-24T13:00:04.184+0000] {taskinstance.py:3132} INFO - Exporting env vars: AIRFLOW_CTX_DAG_OWNER='Oshith Roshantha' AIRFLOW_CTX_DAG_ID='etl_Pipeline' AIRFLOW_CTX_TASK_ID='fetchData' AIRFLOW_CTX_EXECUTION_DATE='2024-11-24T12:00:00+00:00' AIRFLOW_CTX_TRY_NUMBER='1' AIRFLOW_CTX_DAG_RUN_ID='scheduled__2024-11-24T12:00:00+00:00'
[2024-11-24T13:00:04.192+0000] {taskinstance.py:731} INFO - ::endgroup::
[2024-11-24T13:00:04.364+0000] {taskinstance.py:3311} ERROR - Task failed with exception
Traceback (most recent call last):
  File "/home/airflow/.local/lib/python3.12/site-packages/airflow/models/taskinstance.py", line 767, in _execute_task
    result = _execute_callable(context=context, **execute_callable_kwargs)
             ^^^^^^^^^^^^^^^^^^^^^^^^^^^^^^^^^^^^^^^^^^^^^^^^^^^^^^^^^^^^^
  File "/home/airflow/.local/lib/python3.12/site-packages/airflow/models/taskinstance.py", line 733, in _execute_callable
    return ExecutionCallableRunner(
           ^^^^^^^^^^^^^^^^^^^^^^^^
  File "/home/airflow/.local/lib/python3.12/site-packages/airflow/utils/operator_helpers.py", line 252, in run
    return self.func(*args, **kwargs)
           ^^^^^^^^^^^^^^^^^^^^^^^^^^
  File "/home/airflow/.local/lib/python3.12/site-packages/airflow/models/baseoperator.py", line 417, in wrapper
    return func(self, *args, **kwargs)
           ^^^^^^^^^^^^^^^^^^^^^^^^^^^
  File "/home/airflow/.local/lib/python3.12/site-packages/airflow/operators/python.py", line 238, in execute
    return_value = self.execute_callable()
                   ^^^^^^^^^^^^^^^^^^^^^^^
  File "/home/airflow/.local/lib/python3.12/site-packages/airflow/operators/python.py", line 256, in execute_callable
    return runner.run(*self.op_args, **self.op_kwargs)
           ^^^^^^^^^^^^^^^^^^^^^^^^^^^^^^^^^^^^^^^^^^^
  File "/home/airflow/.local/lib/python3.12/site-packages/airflow/utils/operator_helpers.py", line 252, in run
    return self.func(*args, **kwargs)
           ^^^^^^^^^^^^^^^^^^^^^^^^^^
  File "/opt/airflow/dags/etlDag.py", line 32, in fetchData
    import src
ModuleNotFoundError: No module named 'src'
[2024-11-24T13:00:04.473+0000] {taskinstance.py:1225} INFO - Marking task as UP_FOR_RETRY. dag_id=etl_Pipeline, task_id=fetchData, run_id=scheduled__2024-11-24T12:00:00+00:00, execution_date=20241124T120000, start_date=20241124T130003, end_date=20241124T130004
[2024-11-24T13:00:04.625+0000] {taskinstance.py:340} INFO - ::group::Post task execution logs
[2024-11-24T13:00:04.627+0000] {standard_task_runner.py:124} ERROR - Failed to execute job 4 for task fetchData (No module named 'src'; 526)
Traceback (most recent call last):
  File "/home/airflow/.local/lib/python3.12/site-packages/airflow/task/task_runner/standard_task_runner.py", line 117, in _start_by_fork
    ret = args.func(args, dag=self.dag)
          ^^^^^^^^^^^^^^^^^^^^^^^^^^^^^
  File "/home/airflow/.local/lib/python3.12/site-packages/airflow/cli/cli_config.py", line 49, in command
    return func(*args, **kwargs)
           ^^^^^^^^^^^^^^^^^^^^^
  File "/home/airflow/.local/lib/python3.12/site-packages/airflow/utils/cli.py", line 116, in wrapper
    return f(*args, **kwargs)
           ^^^^^^^^^^^^^^^^^^
  File "/home/airflow/.local/lib/python3.12/site-packages/airflow/cli/commands/task_command.py", line 483, in task_run
    task_return_code = _run_task_by_selected_method(args, _dag, ti)
                       ^^^^^^^^^^^^^^^^^^^^^^^^^^^^^^^^^^^^^^^^^^^^
  File "/home/airflow/.local/lib/python3.12/site-packages/airflow/cli/commands/task_command.py", line 256, in _run_task_by_selected_method
    return _run_raw_task(args, ti)
           ^^^^^^^^^^^^^^^^^^^^^^^
  File "/home/airflow/.local/lib/python3.12/site-packages/airflow/cli/commands/task_command.py", line 341, in _run_raw_task
    return ti._run_raw_task(
           ^^^^^^^^^^^^^^^^^
  File "/home/airflow/.local/lib/python3.12/site-packages/airflow/utils/session.py", line 97, in wrapper
    return func(*args, session=session, **kwargs)
           ^^^^^^^^^^^^^^^^^^^^^^^^^^^^^^^^^^^^^^
  File "/home/airflow/.local/lib/python3.12/site-packages/airflow/models/taskinstance.py", line 3005, in _run_raw_task
    return _run_raw_task(
           ^^^^^^^^^^^^^^
  File "/home/airflow/.local/lib/python3.12/site-packages/airflow/models/taskinstance.py", line 273, in _run_raw_task
    TaskInstance._execute_task_with_callbacks(
  File "/home/airflow/.local/lib/python3.12/site-packages/airflow/models/taskinstance.py", line 3159, in _execute_task_with_callbacks
    result = self._execute_task(context, task_orig)
             ^^^^^^^^^^^^^^^^^^^^^^^^^^^^^^^^^^^^^^
  File "/home/airflow/.local/lib/python3.12/site-packages/airflow/models/taskinstance.py", line 3183, in _execute_task
    return _execute_task(self, context, task_orig)
           ^^^^^^^^^^^^^^^^^^^^^^^^^^^^^^^^^^^^^^^
  File "/home/airflow/.local/lib/python3.12/site-packages/airflow/models/taskinstance.py", line 767, in _execute_task
    result = _execute_callable(context=context, **execute_callable_kwargs)
             ^^^^^^^^^^^^^^^^^^^^^^^^^^^^^^^^^^^^^^^^^^^^^^^^^^^^^^^^^^^^^
  File "/home/airflow/.local/lib/python3.12/site-packages/airflow/models/taskinstance.py", line 733, in _execute_callable
    return ExecutionCallableRunner(
           ^^^^^^^^^^^^^^^^^^^^^^^^
  File "/home/airflow/.local/lib/python3.12/site-packages/airflow/utils/operator_helpers.py", line 252, in run
    return self.func(*args, **kwargs)
           ^^^^^^^^^^^^^^^^^^^^^^^^^^
  File "/home/airflow/.local/lib/python3.12/site-packages/airflow/models/baseoperator.py", line 417, in wrapper
    return func(self, *args, **kwargs)
           ^^^^^^^^^^^^^^^^^^^^^^^^^^^
  File "/home/airflow/.local/lib/python3.12/site-packages/airflow/operators/python.py", line 238, in execute
    return_value = self.execute_callable()
                   ^^^^^^^^^^^^^^^^^^^^^^^
  File "/home/airflow/.local/lib/python3.12/site-packages/airflow/operators/python.py", line 256, in execute_callable
    return runner.run(*self.op_args, **self.op_kwargs)
           ^^^^^^^^^^^^^^^^^^^^^^^^^^^^^^^^^^^^^^^^^^^
  File "/home/airflow/.local/lib/python3.12/site-packages/airflow/utils/operator_helpers.py", line 252, in run
    return self.func(*args, **kwargs)
           ^^^^^^^^^^^^^^^^^^^^^^^^^^
  File "/opt/airflow/dags/etlDag.py", line 32, in fetchData
    import src
ModuleNotFoundError: No module named 'src'
[2024-11-24T13:00:04.744+0000] {local_task_job_runner.py:266} INFO - Task exited with return code 1
[2024-11-24T13:00:04.839+0000] {taskinstance.py:3895} INFO - 0 downstream tasks scheduled from follow-on schedule check
[2024-11-24T13:00:04.844+0000] {local_task_job_runner.py:245} INFO - ::endgroup::
[2024-11-24T13:58:04.295+0000] {local_task_job_runner.py:123} INFO - ::group::Pre task execution logs
[2024-11-24T13:58:04.392+0000] {taskinstance.py:2613} INFO - Dependencies all met for dep_context=non-requeueable deps ti=<TaskInstance: etl_Pipeline.fetchData scheduled__2024-11-24T12:00:00+00:00 [queued]>
[2024-11-24T13:58:04.412+0000] {taskinstance.py:2613} INFO - Dependencies all met for dep_context=requeueable deps ti=<TaskInstance: etl_Pipeline.fetchData scheduled__2024-11-24T12:00:00+00:00 [queued]>
[2024-11-24T13:58:04.413+0000] {taskinstance.py:2866} INFO - Starting attempt 1 of 4
[2024-11-24T13:58:04.453+0000] {taskinstance.py:2889} INFO - Executing <Task(PythonOperator): fetchData> on 2024-11-24 12:00:00+00:00
[2024-11-24T13:58:04.620+0000] {logging_mixin.py:190} WARNING - /home/***/.local/lib/python3.12/site-packages/***/task/task_runner/standard_task_runner.py:70 DeprecationWarning: This process (pid=339) is multi-threaded, use of fork() may lead to deadlocks in the child.
[2024-11-24T13:58:04.643+0000] {standard_task_runner.py:72} INFO - Started process 353 to run task
[2024-11-24T13:58:04.701+0000] {standard_task_runner.py:104} INFO - Running: ['***', 'tasks', 'run', 'etl_Pipeline', 'fetchData', 'scheduled__2024-11-24T12:00:00+00:00', '--job-id', '4', '--raw', '--subdir', 'DAGS_FOLDER/etlDag.py', '--cfg-path', '/tmp/tmprkacd2e8']
[2024-11-24T13:58:04.795+0000] {standard_task_runner.py:105} INFO - Job 4: Subtask fetchData
[2024-11-24T13:58:05.207+0000] {task_command.py:467} INFO - Running <TaskInstance: etl_Pipeline.fetchData scheduled__2024-11-24T12:00:00+00:00 [running]> on host c27535c52186
[2024-11-24T13:58:05.814+0000] {taskinstance.py:3132} INFO - Exporting env vars: AIRFLOW_CTX_DAG_OWNER='Oshith Roshantha' AIRFLOW_CTX_DAG_ID='etl_Pipeline' AIRFLOW_CTX_TASK_ID='fetchData' AIRFLOW_CTX_EXECUTION_DATE='2024-11-24T12:00:00+00:00' AIRFLOW_CTX_TRY_NUMBER='1' AIRFLOW_CTX_DAG_RUN_ID='scheduled__2024-11-24T12:00:00+00:00'
[2024-11-24T13:58:05.816+0000] {taskinstance.py:731} INFO - ::endgroup::
[2024-11-24T13:58:05.916+0000] {taskinstance.py:3311} ERROR - Task failed with exception
Traceback (most recent call last):
  File "/home/airflow/.local/lib/python3.12/site-packages/airflow/models/taskinstance.py", line 767, in _execute_task
    result = _execute_callable(context=context, **execute_callable_kwargs)
             ^^^^^^^^^^^^^^^^^^^^^^^^^^^^^^^^^^^^^^^^^^^^^^^^^^^^^^^^^^^^^
  File "/home/airflow/.local/lib/python3.12/site-packages/airflow/models/taskinstance.py", line 733, in _execute_callable
    return ExecutionCallableRunner(
           ^^^^^^^^^^^^^^^^^^^^^^^^
  File "/home/airflow/.local/lib/python3.12/site-packages/airflow/utils/operator_helpers.py", line 252, in run
    return self.func(*args, **kwargs)
           ^^^^^^^^^^^^^^^^^^^^^^^^^^
  File "/home/airflow/.local/lib/python3.12/site-packages/airflow/models/baseoperator.py", line 417, in wrapper
    return func(self, *args, **kwargs)
           ^^^^^^^^^^^^^^^^^^^^^^^^^^^
  File "/home/airflow/.local/lib/python3.12/site-packages/airflow/operators/python.py", line 238, in execute
    return_value = self.execute_callable()
                   ^^^^^^^^^^^^^^^^^^^^^^^
  File "/home/airflow/.local/lib/python3.12/site-packages/airflow/operators/python.py", line 256, in execute_callable
    return runner.run(*self.op_args, **self.op_kwargs)
           ^^^^^^^^^^^^^^^^^^^^^^^^^^^^^^^^^^^^^^^^^^^
  File "/home/airflow/.local/lib/python3.12/site-packages/airflow/utils/operator_helpers.py", line 252, in run
    return self.func(*args, **kwargs)
           ^^^^^^^^^^^^^^^^^^^^^^^^^^
  File "/opt/airflow/dags/etlDag.py", line 33, in fetchData
    rawData = dataRetrival.fetchFromApi(startTime, endTime)
              ^^^^^^^^^^^^^^^^^^^^^^^^^^^^^^^^^^^^^^^^^^^^^
  File "/opt/airflow/dags/src/dataRetrival.py", line 11, in fetchFromApi
    response=requests.get('https://earthquake.usgs.gov/fdsnws/event/1/query',params=params)
             ^^^^^^^^^^^^^^^^^^^^^^^^^^^^^^^^^^^^^^^^^^^^^^^^^^^^^^^^^^^^^^^^^^^^^^^^^^^^^^
  File "/home/airflow/.local/lib/python3.12/site-packages/requests/api.py", line 73, in get
    return request("get", url, params=params, **kwargs)
           ^^^^^^^^^^^^^^^^^^^^^^^^^^^^^^^^^^^^^^^^^^^^
  File "/home/airflow/.local/lib/python3.12/site-packages/requests/api.py", line 59, in request
    return session.request(method=method, url=url, **kwargs)
           ^^^^^^^^^^^^^^^^^^^^^^^^^^^^^^^^^^^^^^^^^^^^^^^^^
  File "/home/airflow/.local/lib/python3.12/site-packages/requests/sessions.py", line 575, in request
    prep = self.prepare_request(req)
           ^^^^^^^^^^^^^^^^^^^^^^^^^
  File "/home/airflow/.local/lib/python3.12/site-packages/requests/sessions.py", line 484, in prepare_request
    p.prepare(
  File "/home/airflow/.local/lib/python3.12/site-packages/requests/models.py", line 367, in prepare
    self.prepare_url(url, params)
  File "/home/airflow/.local/lib/python3.12/site-packages/requests/models.py", line 473, in prepare_url
    enc_params = self._encode_params(params)
                 ^^^^^^^^^^^^^^^^^^^^^^^^^^^
  File "/home/airflow/.local/lib/python3.12/site-packages/requests/models.py", line 124, in _encode_params
    for v in vs:
             ^^
TypeError: 'DateTime' object is not iterable
[2024-11-24T13:58:06.015+0000] {taskinstance.py:1225} INFO - Marking task as UP_FOR_RETRY. dag_id=etl_Pipeline, task_id=fetchData, run_id=scheduled__2024-11-24T12:00:00+00:00, execution_date=20241124T120000, start_date=20241124T135804, end_date=20241124T135806
[2024-11-24T13:58:06.054+0000] {taskinstance.py:340} INFO - ::group::Post task execution logs
[2024-11-24T13:58:06.055+0000] {standard_task_runner.py:124} ERROR - Failed to execute job 4 for task fetchData ('DateTime' object is not iterable; 353)
Traceback (most recent call last):
  File "/home/airflow/.local/lib/python3.12/site-packages/airflow/task/task_runner/standard_task_runner.py", line 117, in _start_by_fork
    ret = args.func(args, dag=self.dag)
          ^^^^^^^^^^^^^^^^^^^^^^^^^^^^^
  File "/home/airflow/.local/lib/python3.12/site-packages/airflow/cli/cli_config.py", line 49, in command
    return func(*args, **kwargs)
           ^^^^^^^^^^^^^^^^^^^^^
  File "/home/airflow/.local/lib/python3.12/site-packages/airflow/utils/cli.py", line 116, in wrapper
    return f(*args, **kwargs)
           ^^^^^^^^^^^^^^^^^^
  File "/home/airflow/.local/lib/python3.12/site-packages/airflow/cli/commands/task_command.py", line 483, in task_run
    task_return_code = _run_task_by_selected_method(args, _dag, ti)
                       ^^^^^^^^^^^^^^^^^^^^^^^^^^^^^^^^^^^^^^^^^^^^
  File "/home/airflow/.local/lib/python3.12/site-packages/airflow/cli/commands/task_command.py", line 256, in _run_task_by_selected_method
    return _run_raw_task(args, ti)
           ^^^^^^^^^^^^^^^^^^^^^^^
  File "/home/airflow/.local/lib/python3.12/site-packages/airflow/cli/commands/task_command.py", line 341, in _run_raw_task
    return ti._run_raw_task(
           ^^^^^^^^^^^^^^^^^
  File "/home/airflow/.local/lib/python3.12/site-packages/airflow/utils/session.py", line 97, in wrapper
    return func(*args, session=session, **kwargs)
           ^^^^^^^^^^^^^^^^^^^^^^^^^^^^^^^^^^^^^^
  File "/home/airflow/.local/lib/python3.12/site-packages/airflow/models/taskinstance.py", line 3005, in _run_raw_task
    return _run_raw_task(
           ^^^^^^^^^^^^^^
  File "/home/airflow/.local/lib/python3.12/site-packages/airflow/models/taskinstance.py", line 273, in _run_raw_task
    TaskInstance._execute_task_with_callbacks(
  File "/home/airflow/.local/lib/python3.12/site-packages/airflow/models/taskinstance.py", line 3159, in _execute_task_with_callbacks
    result = self._execute_task(context, task_orig)
             ^^^^^^^^^^^^^^^^^^^^^^^^^^^^^^^^^^^^^^
  File "/home/airflow/.local/lib/python3.12/site-packages/airflow/models/taskinstance.py", line 3183, in _execute_task
    return _execute_task(self, context, task_orig)
           ^^^^^^^^^^^^^^^^^^^^^^^^^^^^^^^^^^^^^^^
  File "/home/airflow/.local/lib/python3.12/site-packages/airflow/models/taskinstance.py", line 767, in _execute_task
    result = _execute_callable(context=context, **execute_callable_kwargs)
             ^^^^^^^^^^^^^^^^^^^^^^^^^^^^^^^^^^^^^^^^^^^^^^^^^^^^^^^^^^^^^
  File "/home/airflow/.local/lib/python3.12/site-packages/airflow/models/taskinstance.py", line 733, in _execute_callable
    return ExecutionCallableRunner(
           ^^^^^^^^^^^^^^^^^^^^^^^^
  File "/home/airflow/.local/lib/python3.12/site-packages/airflow/utils/operator_helpers.py", line 252, in run
    return self.func(*args, **kwargs)
           ^^^^^^^^^^^^^^^^^^^^^^^^^^
  File "/home/airflow/.local/lib/python3.12/site-packages/airflow/models/baseoperator.py", line 417, in wrapper
    return func(self, *args, **kwargs)
           ^^^^^^^^^^^^^^^^^^^^^^^^^^^
  File "/home/airflow/.local/lib/python3.12/site-packages/airflow/operators/python.py", line 238, in execute
    return_value = self.execute_callable()
                   ^^^^^^^^^^^^^^^^^^^^^^^
  File "/home/airflow/.local/lib/python3.12/site-packages/airflow/operators/python.py", line 256, in execute_callable
    return runner.run(*self.op_args, **self.op_kwargs)
           ^^^^^^^^^^^^^^^^^^^^^^^^^^^^^^^^^^^^^^^^^^^
  File "/home/airflow/.local/lib/python3.12/site-packages/airflow/utils/operator_helpers.py", line 252, in run
    return self.func(*args, **kwargs)
           ^^^^^^^^^^^^^^^^^^^^^^^^^^
  File "/opt/airflow/dags/etlDag.py", line 33, in fetchData
    rawData = dataRetrival.fetchFromApi(startTime, endTime)
              ^^^^^^^^^^^^^^^^^^^^^^^^^^^^^^^^^^^^^^^^^^^^^
  File "/opt/airflow/dags/src/dataRetrival.py", line 11, in fetchFromApi
    response=requests.get('https://earthquake.usgs.gov/fdsnws/event/1/query',params=params)
             ^^^^^^^^^^^^^^^^^^^^^^^^^^^^^^^^^^^^^^^^^^^^^^^^^^^^^^^^^^^^^^^^^^^^^^^^^^^^^^
  File "/home/airflow/.local/lib/python3.12/site-packages/requests/api.py", line 73, in get
    return request("get", url, params=params, **kwargs)
           ^^^^^^^^^^^^^^^^^^^^^^^^^^^^^^^^^^^^^^^^^^^^
  File "/home/airflow/.local/lib/python3.12/site-packages/requests/api.py", line 59, in request
    return session.request(method=method, url=url, **kwargs)
           ^^^^^^^^^^^^^^^^^^^^^^^^^^^^^^^^^^^^^^^^^^^^^^^^^
  File "/home/airflow/.local/lib/python3.12/site-packages/requests/sessions.py", line 575, in request
    prep = self.prepare_request(req)
           ^^^^^^^^^^^^^^^^^^^^^^^^^
  File "/home/airflow/.local/lib/python3.12/site-packages/requests/sessions.py", line 484, in prepare_request
    p.prepare(
  File "/home/airflow/.local/lib/python3.12/site-packages/requests/models.py", line 367, in prepare
    self.prepare_url(url, params)
  File "/home/airflow/.local/lib/python3.12/site-packages/requests/models.py", line 473, in prepare_url
    enc_params = self._encode_params(params)
                 ^^^^^^^^^^^^^^^^^^^^^^^^^^^
  File "/home/airflow/.local/lib/python3.12/site-packages/requests/models.py", line 124, in _encode_params
    for v in vs:
             ^^
TypeError: 'DateTime' object is not iterable
[2024-11-24T13:58:06.099+0000] {local_task_job_runner.py:266} INFO - Task exited with return code 1
[2024-11-24T13:58:06.136+0000] {taskinstance.py:3895} INFO - 0 downstream tasks scheduled from follow-on schedule check
[2024-11-24T13:58:06.140+0000] {local_task_job_runner.py:245} INFO - ::endgroup::
