[2024-11-25T07:18:45.547+0000] {local_task_job_runner.py:123} INFO - ::group::Pre task execution logs
[2024-11-25T07:18:45.568+0000] {taskinstance.py:2613} INFO - Dependencies all met for dep_context=non-requeueable deps ti=<TaskInstance: etl_PipelineV23.pushDataToAzure scheduled__2024-11-25T06:00:00+00:00 [queued]>
[2024-11-25T07:18:45.578+0000] {taskinstance.py:2613} INFO - Dependencies all met for dep_context=requeueable deps ti=<TaskInstance: etl_PipelineV23.pushDataToAzure scheduled__2024-11-25T06:00:00+00:00 [queued]>
[2024-11-25T07:18:45.579+0000] {taskinstance.py:2866} INFO - Starting attempt 1 of 4
[2024-11-25T07:18:45.592+0000] {taskinstance.py:2889} INFO - Executing <Task(PythonOperator): pushDataToAzure> on 2024-11-25 06:00:00+00:00
[2024-11-25T07:18:45.603+0000] {standard_task_runner.py:104} INFO - Running: ['***', 'tasks', 'run', 'etl_PipelineV23', 'pushDataToAzure', 'scheduled__2024-11-25T06:00:00+00:00', '--job-id', '6', '--raw', '--subdir', 'DAGS_FOLDER/etlDag.py', '--cfg-path', '/tmp/tmpfjqxnnas']
[2024-11-25T07:18:45.604+0000] {logging_mixin.py:190} WARNING - /home/***/.local/lib/python3.12/site-packages/***/task/task_runner/standard_task_runner.py:70 DeprecationWarning: This process (pid=331) is multi-threaded, use of fork() may lead to deadlocks in the child.
[2024-11-25T07:18:45.606+0000] {standard_task_runner.py:105} INFO - Job 6: Subtask pushDataToAzure
[2024-11-25T07:18:45.607+0000] {standard_task_runner.py:72} INFO - Started process 341 to run task
[2024-11-25T07:18:45.649+0000] {task_command.py:467} INFO - Running <TaskInstance: etl_PipelineV23.pushDataToAzure scheduled__2024-11-25T06:00:00+00:00 [running]> on host 7939e06e2b4b
[2024-11-25T07:18:45.872+0000] {taskinstance.py:3132} INFO - Exporting env vars: AIRFLOW_CTX_DAG_OWNER='Oshith Roshantha' AIRFLOW_CTX_DAG_ID='etl_PipelineV23' AIRFLOW_CTX_TASK_ID='pushDataToAzure' AIRFLOW_CTX_EXECUTION_DATE='2024-11-25T06:00:00+00:00' AIRFLOW_CTX_TRY_NUMBER='1' AIRFLOW_CTX_DAG_RUN_ID='scheduled__2024-11-25T06:00:00+00:00'
[2024-11-25T07:18:45.874+0000] {taskinstance.py:731} INFO - ::endgroup::
[2024-11-25T07:18:45.916+0000] {environment.py:115} INFO - No environment configuration found.
[2024-11-25T07:18:45.923+0000] {managed_identity.py:117} INFO - ManagedIdentityCredential will use IMDS
[2024-11-25T07:18:45.932+0000] {_universal.py:509} INFO - Request URL: 'http://169.254.169.254/metadata/identity/oauth2/token?api-version=REDACTED&resource=REDACTED'
Request method: 'GET'
Request headers:
    'User-Agent': 'azsdk-python-identity/1.19.0 Python/3.12.7 (Linux-5.15.153.1-microsoft-standard-WSL2-x86_64-with-glibc2.36)'
No body was attached to the request
[2024-11-25T07:18:46.131+0000] {chained.py:218} WARNING - DefaultAzureCredential failed to retrieve a token from the included credentials.
Attempted credentials:
	EnvironmentCredential: EnvironmentCredential authentication unavailable. Environment variables are not fully configured.
Visit https://aka.ms/azsdk/python/identity/environmentcredential/troubleshoot to troubleshoot this issue.
	ManagedIdentityCredential: ManagedIdentityCredential authentication unavailable, no response from the IMDS endpoint.
	SharedTokenCacheCredential: SharedTokenCacheCredential authentication unavailable. No accounts were found in the cache.
	AzureCliCredential: Azure CLI not found on path
	AzurePowerShellCredential: PowerShell is not installed
	AzureDeveloperCliCredential: Azure Developer CLI could not be found. Please visit https://aka.ms/azure-dev for installation instructions and then,once installed, authenticate to your Azure account using 'azd auth login'.
To mitigate this issue, please refer to the troubleshooting guidelines here at https://aka.ms/azsdk/python/identity/defaultazurecredential/troubleshoot.
[2024-11-25T07:19:05.503+0000] {_universal.py:509} INFO - Request URL: 'http://169.254.169.254/metadata/identity/oauth2/token?api-version=REDACTED&resource=REDACTED'
Request method: 'GET'
Request headers:
    'User-Agent': 'azsdk-python-identity/1.19.0 Python/3.12.7 (Linux-5.15.153.1-microsoft-standard-WSL2-x86_64-with-glibc2.36)'
No body was attached to the request
[2024-11-25T07:19:05.516+0000] {chained.py:218} WARNING - DefaultAzureCredential failed to retrieve a token from the included credentials.
Attempted credentials:
	EnvironmentCredential: EnvironmentCredential authentication unavailable. Environment variables are not fully configured.
Visit https://aka.ms/azsdk/python/identity/environmentcredential/troubleshoot to troubleshoot this issue.
	ManagedIdentityCredential: ManagedIdentityCredential authentication unavailable, no response from the IMDS endpoint.
	SharedTokenCacheCredential: SharedTokenCacheCredential authentication unavailable. No accounts were found in the cache.
	AzureCliCredential: Azure CLI not found on path
	AzurePowerShellCredential: PowerShell is not installed
	AzureDeveloperCliCredential: Azure Developer CLI could not be found. Please visit https://aka.ms/azure-dev for installation instructions and then,once installed, authenticate to your Azure account using 'azd auth login'.
To mitigate this issue, please refer to the troubleshooting guidelines here at https://aka.ms/azsdk/python/identity/defaultazurecredential/troubleshoot.
[2024-11-25T07:19:26.603+0000] {_universal.py:509} INFO - Request URL: 'http://169.254.169.254/metadata/identity/oauth2/token?api-version=REDACTED&resource=REDACTED'
Request method: 'GET'
Request headers:
    'User-Agent': 'azsdk-python-identity/1.19.0 Python/3.12.7 (Linux-5.15.153.1-microsoft-standard-WSL2-x86_64-with-glibc2.36)'
No body was attached to the request
[2024-11-25T07:19:26.610+0000] {chained.py:218} WARNING - DefaultAzureCredential failed to retrieve a token from the included credentials.
Attempted credentials:
	EnvironmentCredential: EnvironmentCredential authentication unavailable. Environment variables are not fully configured.
Visit https://aka.ms/azsdk/python/identity/environmentcredential/troubleshoot to troubleshoot this issue.
	ManagedIdentityCredential: ManagedIdentityCredential authentication unavailable, no response from the IMDS endpoint.
	SharedTokenCacheCredential: SharedTokenCacheCredential authentication unavailable. No accounts were found in the cache.
	AzureCliCredential: Azure CLI not found on path
	AzurePowerShellCredential: PowerShell is not installed
	AzureDeveloperCliCredential: Azure Developer CLI could not be found. Please visit https://aka.ms/azure-dev for installation instructions and then,once installed, authenticate to your Azure account using 'azd auth login'.
To mitigate this issue, please refer to the troubleshooting guidelines here at https://aka.ms/azsdk/python/identity/defaultazurecredential/troubleshoot.
[2024-11-25T07:20:10.619+0000] {_universal.py:509} INFO - Request URL: 'http://169.254.169.254/metadata/identity/oauth2/token?api-version=REDACTED&resource=REDACTED'
Request method: 'GET'
Request headers:
    'User-Agent': 'azsdk-python-identity/1.19.0 Python/3.12.7 (Linux-5.15.153.1-microsoft-standard-WSL2-x86_64-with-glibc2.36)'
No body was attached to the request
[2024-11-25T07:20:10.636+0000] {chained.py:218} WARNING - DefaultAzureCredential failed to retrieve a token from the included credentials.
Attempted credentials:
	EnvironmentCredential: EnvironmentCredential authentication unavailable. Environment variables are not fully configured.
Visit https://aka.ms/azsdk/python/identity/environmentcredential/troubleshoot to troubleshoot this issue.
	ManagedIdentityCredential: ManagedIdentityCredential authentication unavailable, no response from the IMDS endpoint.
	SharedTokenCacheCredential: SharedTokenCacheCredential authentication unavailable. No accounts were found in the cache.
	AzureCliCredential: Azure CLI not found on path
	AzurePowerShellCredential: PowerShell is not installed
	AzureDeveloperCliCredential: Azure Developer CLI could not be found. Please visit https://aka.ms/azure-dev for installation instructions and then,once installed, authenticate to your Azure account using 'azd auth login'.
To mitigate this issue, please refer to the troubleshooting guidelines here at https://aka.ms/azsdk/python/identity/defaultazurecredential/troubleshoot.
[2024-11-25T07:20:10.673+0000] {_universal.py:509} INFO - Request URL: 'http://169.254.169.254/metadata/identity/oauth2/token?api-version=REDACTED&resource=REDACTED'
Request method: 'GET'
Request headers:
    'User-Agent': 'azsdk-python-identity/1.19.0 Python/3.12.7 (Linux-5.15.153.1-microsoft-standard-WSL2-x86_64-with-glibc2.36)'
No body was attached to the request
[2024-11-25T07:20:10.678+0000] {chained.py:218} WARNING - DefaultAzureCredential failed to retrieve a token from the included credentials.
Attempted credentials:
	EnvironmentCredential: EnvironmentCredential authentication unavailable. Environment variables are not fully configured.
Visit https://aka.ms/azsdk/python/identity/environmentcredential/troubleshoot to troubleshoot this issue.
	ManagedIdentityCredential: ManagedIdentityCredential authentication unavailable, no response from the IMDS endpoint.
	SharedTokenCacheCredential: SharedTokenCacheCredential authentication unavailable. No accounts were found in the cache.
	AzureCliCredential: Azure CLI not found on path
	AzurePowerShellCredential: PowerShell is not installed
	AzureDeveloperCliCredential: Azure Developer CLI could not be found. Please visit https://aka.ms/azure-dev for installation instructions and then,once installed, authenticate to your Azure account using 'azd auth login'.
To mitigate this issue, please refer to the troubleshooting guidelines here at https://aka.ms/azsdk/python/identity/defaultazurecredential/troubleshoot.
[2024-11-25T07:20:31.540+0000] {_universal.py:509} INFO - Request URL: 'http://169.254.169.254/metadata/identity/oauth2/token?api-version=REDACTED&resource=REDACTED'
Request method: 'GET'
Request headers:
    'User-Agent': 'azsdk-python-identity/1.19.0 Python/3.12.7 (Linux-5.15.153.1-microsoft-standard-WSL2-x86_64-with-glibc2.36)'
No body was attached to the request
[2024-11-25T07:20:31.553+0000] {chained.py:218} WARNING - DefaultAzureCredential failed to retrieve a token from the included credentials.
Attempted credentials:
	EnvironmentCredential: EnvironmentCredential authentication unavailable. Environment variables are not fully configured.
Visit https://aka.ms/azsdk/python/identity/environmentcredential/troubleshoot to troubleshoot this issue.
	ManagedIdentityCredential: ManagedIdentityCredential authentication unavailable, no response from the IMDS endpoint.
	SharedTokenCacheCredential: SharedTokenCacheCredential authentication unavailable. No accounts were found in the cache.
	AzureCliCredential: Azure CLI not found on path
	AzurePowerShellCredential: PowerShell is not installed
	AzureDeveloperCliCredential: Azure Developer CLI could not be found. Please visit https://aka.ms/azure-dev for installation instructions and then,once installed, authenticate to your Azure account using 'azd auth login'.
To mitigate this issue, please refer to the troubleshooting guidelines here at https://aka.ms/azsdk/python/identity/defaultazurecredential/troubleshoot.
[2024-11-25T07:20:56.994+0000] {_universal.py:509} INFO - Request URL: 'http://169.254.169.254/metadata/identity/oauth2/token?api-version=REDACTED&resource=REDACTED'
Request method: 'GET'
Request headers:
    'User-Agent': 'azsdk-python-identity/1.19.0 Python/3.12.7 (Linux-5.15.153.1-microsoft-standard-WSL2-x86_64-with-glibc2.36)'
No body was attached to the request
[2024-11-25T07:20:57.008+0000] {chained.py:218} WARNING - DefaultAzureCredential failed to retrieve a token from the included credentials.
Attempted credentials:
	EnvironmentCredential: EnvironmentCredential authentication unavailable. Environment variables are not fully configured.
Visit https://aka.ms/azsdk/python/identity/environmentcredential/troubleshoot to troubleshoot this issue.
	ManagedIdentityCredential: ManagedIdentityCredential authentication unavailable, no response from the IMDS endpoint.
	SharedTokenCacheCredential: SharedTokenCacheCredential authentication unavailable. No accounts were found in the cache.
	AzureCliCredential: Azure CLI not found on path
	AzurePowerShellCredential: PowerShell is not installed
	AzureDeveloperCliCredential: Azure Developer CLI could not be found. Please visit https://aka.ms/azure-dev for installation instructions and then,once installed, authenticate to your Azure account using 'azd auth login'.
To mitigate this issue, please refer to the troubleshooting guidelines here at https://aka.ms/azsdk/python/identity/defaultazurecredential/troubleshoot.
[2024-11-25T07:21:37.759+0000] {_universal.py:509} INFO - Request URL: 'http://169.254.169.254/metadata/identity/oauth2/token?api-version=REDACTED&resource=REDACTED'
Request method: 'GET'
Request headers:
    'User-Agent': 'azsdk-python-identity/1.19.0 Python/3.12.7 (Linux-5.15.153.1-microsoft-standard-WSL2-x86_64-with-glibc2.36)'
No body was attached to the request
[2024-11-25T07:21:37.782+0000] {chained.py:218} WARNING - DefaultAzureCredential failed to retrieve a token from the included credentials.
Attempted credentials:
	EnvironmentCredential: EnvironmentCredential authentication unavailable. Environment variables are not fully configured.
Visit https://aka.ms/azsdk/python/identity/environmentcredential/troubleshoot to troubleshoot this issue.
	ManagedIdentityCredential: ManagedIdentityCredential authentication unavailable, no response from the IMDS endpoint.
	SharedTokenCacheCredential: SharedTokenCacheCredential authentication unavailable. No accounts were found in the cache.
	AzureCliCredential: Azure CLI not found on path
	AzurePowerShellCredential: PowerShell is not installed
	AzureDeveloperCliCredential: Azure Developer CLI could not be found. Please visit https://aka.ms/azure-dev for installation instructions and then,once installed, authenticate to your Azure account using 'azd auth login'.
To mitigate this issue, please refer to the troubleshooting guidelines here at https://aka.ms/azsdk/python/identity/defaultazurecredential/troubleshoot.
[2024-11-25T07:21:37.926+0000] {taskinstance.py:3311} ERROR - Task failed with exception
Traceback (most recent call last):
  File "/home/airflow/.local/lib/python3.12/site-packages/airflow/models/taskinstance.py", line 767, in _execute_task
    result = _execute_callable(context=context, **execute_callable_kwargs)
             ^^^^^^^^^^^^^^^^^^^^^^^^^^^^^^^^^^^^^^^^^^^^^^^^^^^^^^^^^^^^^
  File "/home/airflow/.local/lib/python3.12/site-packages/airflow/models/taskinstance.py", line 733, in _execute_callable
    return ExecutionCallableRunner(
           ^^^^^^^^^^^^^^^^^^^^^^^^
  File "/home/airflow/.local/lib/python3.12/site-packages/airflow/utils/operator_helpers.py", line 252, in run
    return self.func(*args, **kwargs)
           ^^^^^^^^^^^^^^^^^^^^^^^^^^
  File "/home/airflow/.local/lib/python3.12/site-packages/airflow/models/baseoperator.py", line 417, in wrapper
    return func(self, *args, **kwargs)
           ^^^^^^^^^^^^^^^^^^^^^^^^^^^
  File "/home/airflow/.local/lib/python3.12/site-packages/airflow/operators/python.py", line 238, in execute
    return_value = self.execute_callable()
                   ^^^^^^^^^^^^^^^^^^^^^^^
  File "/home/airflow/.local/lib/python3.12/site-packages/airflow/operators/python.py", line 256, in execute_callable
    return runner.run(*self.op_args, **self.op_kwargs)
           ^^^^^^^^^^^^^^^^^^^^^^^^^^^^^^^^^^^^^^^^^^^
  File "/home/airflow/.local/lib/python3.12/site-packages/airflow/utils/operator_helpers.py", line 252, in run
    return self.func(*args, **kwargs)
           ^^^^^^^^^^^^^^^^^^^^^^^^^^
  File "/opt/airflow/dags/etlDag.py", line 60, in pushDataToAzure
    pushToLake.pushToAzure(transformedData)
  File "/opt/airflow/dags/src/pushToLake.py", line 28, in pushToAzure
    blobClient.upload_blob(uniqueJsonData, overwrite=True)
  File "/home/airflow/.local/lib/python3.12/site-packages/azure/core/tracing/decorator.py", line 105, in wrapper_use_tracer
    return func(*args, **kwargs)
           ^^^^^^^^^^^^^^^^^^^^^
  File "/home/airflow/.local/lib/python3.12/site-packages/azure/storage/blob/_blob_client.py", line 605, in upload_blob
    return upload_block_blob(**options)
           ^^^^^^^^^^^^^^^^^^^^^^^^^^^^
  File "/home/airflow/.local/lib/python3.12/site-packages/azure/storage/blob/_upload_helpers.py", line 197, in upload_block_blob
    process_storage_error(error)
  File "/home/airflow/.local/lib/python3.12/site-packages/azure/storage/blob/_shared/response_handlers.py", line 92, in process_storage_error
    raise storage_error
  File "/home/airflow/.local/lib/python3.12/site-packages/azure/storage/blob/_upload_helpers.py", line 105, in upload_block_blob
    response = client.upload(
               ^^^^^^^^^^^^^^
  File "/home/airflow/.local/lib/python3.12/site-packages/azure/core/tracing/decorator.py", line 105, in wrapper_use_tracer
    return func(*args, **kwargs)
           ^^^^^^^^^^^^^^^^^^^^^
  File "/home/airflow/.local/lib/python3.12/site-packages/azure/storage/blob/_generated/operations/_block_blob_operations.py", line 876, in upload
    pipeline_response: PipelineResponse = self._client._pipeline.run(  # pylint: disable=protected-access
                                          ^^^^^^^^^^^^^^^^^^^^^^^^^^^^^^^^^^^^^^^^^^^^^^^^^^^^^^^^^^^^^^^
  File "/home/airflow/.local/lib/python3.12/site-packages/azure/core/pipeline/_base.py", line 240, in run
    return first_node.send(pipeline_request)
           ^^^^^^^^^^^^^^^^^^^^^^^^^^^^^^^^^
  File "/home/airflow/.local/lib/python3.12/site-packages/azure/core/pipeline/_base.py", line 96, in send
    response = self.next.send(request)
               ^^^^^^^^^^^^^^^^^^^^^^^
  File "/home/airflow/.local/lib/python3.12/site-packages/azure/core/pipeline/_base.py", line 96, in send
    response = self.next.send(request)
               ^^^^^^^^^^^^^^^^^^^^^^^
  File "/home/airflow/.local/lib/python3.12/site-packages/azure/core/pipeline/_base.py", line 96, in send
    response = self.next.send(request)
               ^^^^^^^^^^^^^^^^^^^^^^^
  [Previous line repeated 2 more times]
  File "/home/airflow/.local/lib/python3.12/site-packages/azure/core/pipeline/policies/_redirect.py", line 204, in send
    response = self.next.send(request)
               ^^^^^^^^^^^^^^^^^^^^^^^
  File "/home/airflow/.local/lib/python3.12/site-packages/azure/core/pipeline/_base.py", line 96, in send
    response = self.next.send(request)
               ^^^^^^^^^^^^^^^^^^^^^^^
  File "/home/airflow/.local/lib/python3.12/site-packages/azure/storage/blob/_shared/policies.py", line 555, in send
    raise err
  File "/home/airflow/.local/lib/python3.12/site-packages/azure/storage/blob/_shared/policies.py", line 527, in send
    response = self.next.send(request)
               ^^^^^^^^^^^^^^^^^^^^^^^
  File "/home/airflow/.local/lib/python3.12/site-packages/azure/core/pipeline/_base.py", line 96, in send
    response = self.next.send(request)
               ^^^^^^^^^^^^^^^^^^^^^^^
  File "/home/airflow/.local/lib/python3.12/site-packages/azure/core/pipeline/_base.py", line 96, in send
    response = self.next.send(request)
               ^^^^^^^^^^^^^^^^^^^^^^^
  File "/home/airflow/.local/lib/python3.12/site-packages/azure/core/pipeline/policies/_authentication.py", line 157, in send
    self.on_request(request)
  File "/home/airflow/.local/lib/python3.12/site-packages/azure/core/pipeline/policies/_authentication.py", line 132, in on_request
    self._request_token(*self._scopes)
  File "/home/airflow/.local/lib/python3.12/site-packages/azure/core/pipeline/policies/_authentication.py", line 108, in _request_token
    self._token = self._get_token(*scopes, **kwargs)
                  ^^^^^^^^^^^^^^^^^^^^^^^^^^^^^^^^^^
  File "/home/airflow/.local/lib/python3.12/site-packages/azure/core/pipeline/policies/_authentication.py", line 98, in _get_token
    return cast(SupportsTokenInfo, self._credential).get_token_info(*scopes, options=options)
           ^^^^^^^^^^^^^^^^^^^^^^^^^^^^^^^^^^^^^^^^^^^^^^^^^^^^^^^^^^^^^^^^^^^^^^^^^^^^^^^^^^
  File "/home/airflow/.local/lib/python3.12/site-packages/azure/identity/_credentials/default.py", line 255, in get_token_info
    token_info = cast(SupportsTokenInfo, super()).get_token_info(*scopes, options=options)
                 ^^^^^^^^^^^^^^^^^^^^^^^^^^^^^^^^^^^^^^^^^^^^^^^^^^^^^^^^^^^^^^^^^^^^^^^^^
  File "/home/airflow/.local/lib/python3.12/site-packages/azure/identity/_credentials/chained.py", line 219, in get_token_info
    raise ClientAuthenticationError(message=message)
azure.core.exceptions.ClientAuthenticationError: DefaultAzureCredential failed to retrieve a token from the included credentials.
Attempted credentials:
	EnvironmentCredential: EnvironmentCredential authentication unavailable. Environment variables are not fully configured.
Visit https://aka.ms/azsdk/python/identity/environmentcredential/troubleshoot to troubleshoot this issue.
	ManagedIdentityCredential: ManagedIdentityCredential authentication unavailable, no response from the IMDS endpoint.
	SharedTokenCacheCredential: SharedTokenCacheCredential authentication unavailable. No accounts were found in the cache.
	AzureCliCredential: Azure CLI not found on path
	AzurePowerShellCredential: PowerShell is not installed
	AzureDeveloperCliCredential: Azure Developer CLI could not be found. Please visit https://aka.ms/azure-dev for installation instructions and then,once installed, authenticate to your Azure account using 'azd auth login'.
To mitigate this issue, please refer to the troubleshooting guidelines here at https://aka.ms/azsdk/python/identity/defaultazurecredential/troubleshoot.
[2024-11-25T07:21:38.863+0000] {taskinstance.py:1225} INFO - Marking task as UP_FOR_RETRY. dag_id=etl_PipelineV23, task_id=pushDataToAzure, run_id=scheduled__2024-11-25T06:00:00+00:00, execution_date=20241125T060000, start_date=20241125T071845, end_date=20241125T072138
[2024-11-25T07:21:39.167+0000] {taskinstance.py:340} INFO - ::group::Post task execution logs
[2024-11-25T07:21:39.239+0000] {standard_task_runner.py:124} ERROR - Failed to execute job 6 for task pushDataToAzure (DefaultAzureCredential failed to retrieve a token from the included credentials.
Attempted credentials:
	EnvironmentCredential: EnvironmentCredential authentication unavailable. Environment variables are not fully configured.
Visit https://aka.ms/azsdk/python/identity/environmentcredential/troubleshoot to troubleshoot this issue.
	ManagedIdentityCredential: ManagedIdentityCredential authentication unavailable, no response from the IMDS endpoint.
	SharedTokenCacheCredential: SharedTokenCacheCredential authentication unavailable. No accounts were found in the cache.
	AzureCliCredential: Azure CLI not found on path
	AzurePowerShellCredential: PowerShell is not installed
	AzureDeveloperCliCredential: Azure Developer CLI could not be found. Please visit https://aka.ms/azure-dev for installation instructions and then,once installed, authenticate to your Azure account using 'azd auth login'.
To mitigate this issue, please refer to the troubleshooting guidelines here at https://aka.ms/azsdk/python/identity/defaultazurecredential/troubleshoot.; 341)
Traceback (most recent call last):
  File "/home/airflow/.local/lib/python3.12/site-packages/airflow/task/task_runner/standard_task_runner.py", line 117, in _start_by_fork
    ret = args.func(args, dag=self.dag)
          ^^^^^^^^^^^^^^^^^^^^^^^^^^^^^
  File "/home/airflow/.local/lib/python3.12/site-packages/airflow/cli/cli_config.py", line 49, in command
    return func(*args, **kwargs)
           ^^^^^^^^^^^^^^^^^^^^^
  File "/home/airflow/.local/lib/python3.12/site-packages/airflow/utils/cli.py", line 116, in wrapper
    return f(*args, **kwargs)
           ^^^^^^^^^^^^^^^^^^
  File "/home/airflow/.local/lib/python3.12/site-packages/airflow/cli/commands/task_command.py", line 483, in task_run
    task_return_code = _run_task_by_selected_method(args, _dag, ti)
                       ^^^^^^^^^^^^^^^^^^^^^^^^^^^^^^^^^^^^^^^^^^^^
  File "/home/airflow/.local/lib/python3.12/site-packages/airflow/cli/commands/task_command.py", line 256, in _run_task_by_selected_method
    return _run_raw_task(args, ti)
           ^^^^^^^^^^^^^^^^^^^^^^^
  File "/home/airflow/.local/lib/python3.12/site-packages/airflow/cli/commands/task_command.py", line 341, in _run_raw_task
    return ti._run_raw_task(
           ^^^^^^^^^^^^^^^^^
  File "/home/airflow/.local/lib/python3.12/site-packages/airflow/utils/session.py", line 97, in wrapper
    return func(*args, session=session, **kwargs)
           ^^^^^^^^^^^^^^^^^^^^^^^^^^^^^^^^^^^^^^
  File "/home/airflow/.local/lib/python3.12/site-packages/airflow/models/taskinstance.py", line 3005, in _run_raw_task
    return _run_raw_task(
           ^^^^^^^^^^^^^^
  File "/home/airflow/.local/lib/python3.12/site-packages/airflow/models/taskinstance.py", line 273, in _run_raw_task
    TaskInstance._execute_task_with_callbacks(
  File "/home/airflow/.local/lib/python3.12/site-packages/airflow/models/taskinstance.py", line 3159, in _execute_task_with_callbacks
    result = self._execute_task(context, task_orig)
             ^^^^^^^^^^^^^^^^^^^^^^^^^^^^^^^^^^^^^^
  File "/home/airflow/.local/lib/python3.12/site-packages/airflow/models/taskinstance.py", line 3183, in _execute_task
    return _execute_task(self, context, task_orig)
           ^^^^^^^^^^^^^^^^^^^^^^^^^^^^^^^^^^^^^^^
  File "/home/airflow/.local/lib/python3.12/site-packages/airflow/models/taskinstance.py", line 767, in _execute_task
    result = _execute_callable(context=context, **execute_callable_kwargs)
             ^^^^^^^^^^^^^^^^^^^^^^^^^^^^^^^^^^^^^^^^^^^^^^^^^^^^^^^^^^^^^
  File "/home/airflow/.local/lib/python3.12/site-packages/airflow/models/taskinstance.py", line 733, in _execute_callable
    return ExecutionCallableRunner(
           ^^^^^^^^^^^^^^^^^^^^^^^^
  File "/home/airflow/.local/lib/python3.12/site-packages/airflow/utils/operator_helpers.py", line 252, in run
    return self.func(*args, **kwargs)
           ^^^^^^^^^^^^^^^^^^^^^^^^^^
  File "/home/airflow/.local/lib/python3.12/site-packages/airflow/models/baseoperator.py", line 417, in wrapper
    return func(self, *args, **kwargs)
           ^^^^^^^^^^^^^^^^^^^^^^^^^^^
  File "/home/airflow/.local/lib/python3.12/site-packages/airflow/operators/python.py", line 238, in execute
    return_value = self.execute_callable()
                   ^^^^^^^^^^^^^^^^^^^^^^^
  File "/home/airflow/.local/lib/python3.12/site-packages/airflow/operators/python.py", line 256, in execute_callable
    return runner.run(*self.op_args, **self.op_kwargs)
           ^^^^^^^^^^^^^^^^^^^^^^^^^^^^^^^^^^^^^^^^^^^
  File "/home/airflow/.local/lib/python3.12/site-packages/airflow/utils/operator_helpers.py", line 252, in run
    return self.func(*args, **kwargs)
           ^^^^^^^^^^^^^^^^^^^^^^^^^^
  File "/opt/airflow/dags/etlDag.py", line 60, in pushDataToAzure
    pushToLake.pushToAzure(transformedData)
  File "/opt/airflow/dags/src/pushToLake.py", line 28, in pushToAzure
    blobClient.upload_blob(uniqueJsonData, overwrite=True)
  File "/home/airflow/.local/lib/python3.12/site-packages/azure/core/tracing/decorator.py", line 105, in wrapper_use_tracer
    return func(*args, **kwargs)
           ^^^^^^^^^^^^^^^^^^^^^
  File "/home/airflow/.local/lib/python3.12/site-packages/azure/storage/blob/_blob_client.py", line 605, in upload_blob
    return upload_block_blob(**options)
           ^^^^^^^^^^^^^^^^^^^^^^^^^^^^
  File "/home/airflow/.local/lib/python3.12/site-packages/azure/storage/blob/_upload_helpers.py", line 197, in upload_block_blob
    process_storage_error(error)
  File "/home/airflow/.local/lib/python3.12/site-packages/azure/storage/blob/_shared/response_handlers.py", line 92, in process_storage_error
    raise storage_error
  File "/home/airflow/.local/lib/python3.12/site-packages/azure/storage/blob/_upload_helpers.py", line 105, in upload_block_blob
    response = client.upload(
               ^^^^^^^^^^^^^^
  File "/home/airflow/.local/lib/python3.12/site-packages/azure/core/tracing/decorator.py", line 105, in wrapper_use_tracer
    return func(*args, **kwargs)
           ^^^^^^^^^^^^^^^^^^^^^
  File "/home/airflow/.local/lib/python3.12/site-packages/azure/storage/blob/_generated/operations/_block_blob_operations.py", line 876, in upload
    pipeline_response: PipelineResponse = self._client._pipeline.run(  # pylint: disable=protected-access
                                          ^^^^^^^^^^^^^^^^^^^^^^^^^^^^^^^^^^^^^^^^^^^^^^^^^^^^^^^^^^^^^^^
  File "/home/airflow/.local/lib/python3.12/site-packages/azure/core/pipeline/_base.py", line 240, in run
    return first_node.send(pipeline_request)
           ^^^^^^^^^^^^^^^^^^^^^^^^^^^^^^^^^
  File "/home/airflow/.local/lib/python3.12/site-packages/azure/core/pipeline/_base.py", line 96, in send
    response = self.next.send(request)
               ^^^^^^^^^^^^^^^^^^^^^^^
  File "/home/airflow/.local/lib/python3.12/site-packages/azure/core/pipeline/_base.py", line 96, in send
    response = self.next.send(request)
               ^^^^^^^^^^^^^^^^^^^^^^^
  File "/home/airflow/.local/lib/python3.12/site-packages/azure/core/pipeline/_base.py", line 96, in send
    response = self.next.send(request)
               ^^^^^^^^^^^^^^^^^^^^^^^
  [Previous line repeated 2 more times]
  File "/home/airflow/.local/lib/python3.12/site-packages/azure/core/pipeline/policies/_redirect.py", line 204, in send
    response = self.next.send(request)
               ^^^^^^^^^^^^^^^^^^^^^^^
  File "/home/airflow/.local/lib/python3.12/site-packages/azure/core/pipeline/_base.py", line 96, in send
    response = self.next.send(request)
               ^^^^^^^^^^^^^^^^^^^^^^^
  File "/home/airflow/.local/lib/python3.12/site-packages/azure/storage/blob/_shared/policies.py", line 555, in send
    raise err
  File "/home/airflow/.local/lib/python3.12/site-packages/azure/storage/blob/_shared/policies.py", line 527, in send
    response = self.next.send(request)
               ^^^^^^^^^^^^^^^^^^^^^^^
  File "/home/airflow/.local/lib/python3.12/site-packages/azure/core/pipeline/_base.py", line 96, in send
    response = self.next.send(request)
               ^^^^^^^^^^^^^^^^^^^^^^^
  File "/home/airflow/.local/lib/python3.12/site-packages/azure/core/pipeline/_base.py", line 96, in send
    response = self.next.send(request)
               ^^^^^^^^^^^^^^^^^^^^^^^
  File "/home/airflow/.local/lib/python3.12/site-packages/azure/core/pipeline/policies/_authentication.py", line 157, in send
    self.on_request(request)
  File "/home/airflow/.local/lib/python3.12/site-packages/azure/core/pipeline/policies/_authentication.py", line 132, in on_request
    self._request_token(*self._scopes)
  File "/home/airflow/.local/lib/python3.12/site-packages/azure/core/pipeline/policies/_authentication.py", line 108, in _request_token
    self._token = self._get_token(*scopes, **kwargs)
                  ^^^^^^^^^^^^^^^^^^^^^^^^^^^^^^^^^^
  File "/home/airflow/.local/lib/python3.12/site-packages/azure/core/pipeline/policies/_authentication.py", line 98, in _get_token
    return cast(SupportsTokenInfo, self._credential).get_token_info(*scopes, options=options)
           ^^^^^^^^^^^^^^^^^^^^^^^^^^^^^^^^^^^^^^^^^^^^^^^^^^^^^^^^^^^^^^^^^^^^^^^^^^^^^^^^^^
  File "/home/airflow/.local/lib/python3.12/site-packages/azure/identity/_credentials/default.py", line 255, in get_token_info
    token_info = cast(SupportsTokenInfo, super()).get_token_info(*scopes, options=options)
                 ^^^^^^^^^^^^^^^^^^^^^^^^^^^^^^^^^^^^^^^^^^^^^^^^^^^^^^^^^^^^^^^^^^^^^^^^^
  File "/home/airflow/.local/lib/python3.12/site-packages/azure/identity/_credentials/chained.py", line 219, in get_token_info
    raise ClientAuthenticationError(message=message)
azure.core.exceptions.ClientAuthenticationError: DefaultAzureCredential failed to retrieve a token from the included credentials.
Attempted credentials:
	EnvironmentCredential: EnvironmentCredential authentication unavailable. Environment variables are not fully configured.
Visit https://aka.ms/azsdk/python/identity/environmentcredential/troubleshoot to troubleshoot this issue.
	ManagedIdentityCredential: ManagedIdentityCredential authentication unavailable, no response from the IMDS endpoint.
	SharedTokenCacheCredential: SharedTokenCacheCredential authentication unavailable. No accounts were found in the cache.
	AzureCliCredential: Azure CLI not found on path
	AzurePowerShellCredential: PowerShell is not installed
	AzureDeveloperCliCredential: Azure Developer CLI could not be found. Please visit https://aka.ms/azure-dev for installation instructions and then,once installed, authenticate to your Azure account using 'azd auth login'.
To mitigate this issue, please refer to the troubleshooting guidelines here at https://aka.ms/azsdk/python/identity/defaultazurecredential/troubleshoot.
[2024-11-25T07:21:39.423+0000] {local_task_job_runner.py:266} INFO - Task exited with return code 1
[2024-11-25T07:21:39.727+0000] {taskinstance.py:3895} INFO - 0 downstream tasks scheduled from follow-on schedule check
[2024-11-25T07:21:39.734+0000] {local_task_job_runner.py:245} INFO - ::endgroup::
